Workbook

Sheet Raw
A1: Account Name | B1: Channel | C1: Ticket Owner | D1: Ticket Number | E1: Subject | F1: Category | G1: Sub Category | H1: Device Name | I1: Serial/Subscription | J1: Device Serial | K1: Rack Number | L1: Device Type | M1: Hostname | N1: Model | O1: Current-FW Version | P1: Replaced Serial Number | Q1: Priority | R1: Status | S1: RCA 2 | T1: Hold Reason | U1: Resolution | V1: Created Time | W1: Resolution Time (min) | X1: Total Resolution Time (min) | Y1: Response Time | Z1: Actual Response Time (min) | AA1: Agreed Response SLA (min) | AB1: Response SLA Status | AC1: First Hold Time | AD1: Last Hold Time | AE1: Total JFL Downtime (Mins)HOLD Minute | AF1: Total Proactive Downtime (Mins)- Actual resolution mint | AG1: Agreed Resolution SLA (min) | AH1: Resolution SLA Status | AI1: Remark | AJ1: Total Minute in 7 Apr 2026 to 6 July - 90 Days X Minute | AK1: Proactive Uptime Mins | AL1: Proactive -Uptime% | AM1: JFL -Uptime Mins | AN1: JFL -Uptime %
A2: Jubilant Foodworks Ltd (JFL) | B2: Alert | C2: Dheerendra Maurya | D2: PRO/INC/41590 | E2: switches went down | F2: Meraki Managed Services | G2: Software / Configuration | H2: Bangalore | I2: Q2MW-DT66-3HKL | J2: Q2MW-DT66-3HKL | K2: SIDE-PLANT1 | L2: SW | M2: SIDE-PLANT1 | N2: MS250-24P | O2: switch-17-1-4 | Q2: Core | R2: Closed | S2: Device Power Issues | T2: power issue | U2: Switch went down due to power issue | V2: 46119.549 | W2: 46119.683 | X2: 192.18 | Y2: 46119.549 | Z2: 0.02 | AA2: 30 | AB2: SLA Met | AC2: 46119.555 | AD2: 46119.681 | AE2: 180.82 | AF2: 11.37 | AG2: 120 | AH2: SLA Met | AJ2: 129600 | AK2: =AJ2-AF2 -> 129588.63 | AL2: =AK2/AJ2*100 -> 99.991227 | AM2: =AJ2-AE2 -> 129419.18 | AN2: =AM2/AJ2*100 -> 99.860478
A3: Jubilant Foodworks Ltd (JFL) | B3: Alert | C3: Dheerendra Maurya | D3: PRO/INC/41597 | E3: Need to Enable VLan 9 - GF-ETP-SW1-Port 45 | F3: Meraki Managed Services | G3: Change Request | H3: Bangalore | J3: Q2QW-CAJU-QVKD | K3: GF-ETP | L3: SW | M3: GF-ETP-SW1 | N3: MS250-48FP | O3: switch-17-1-4 | Q3: P4 | R3: Closed | S3: New Configuration | T3: client site activity | U3: I have Enabled VLan 9 - GF-ETP-SW1-Port 45 | V3: 46119.603 | W3: 46119.636 | X3: 47.08 | Y3: 46119.603 | Z3: 0 | AA3: 30 | AB3: SLA Met | AC3: 46119.605 | AD3: 46119.63 | AE3: 35.7 | AF3: 11.38 | AG3: 2880 | AH3: SLA Met | AJ3: 129600 | AK3: =AJ3-AF3 -> 129588.62 | AL3: =AK3/AJ3*100 -> 99.991219 | AM3: =AJ3-AE3 -> 129564.3 | AN3: =AM3/AJ3*100 -> 99.972454
A4: Jubilant Foodworks Ltd (JFL) | B4: Alert | C4: John Ashis Roy | D4: PRO/INC/41621 | E4: aps went down | F4: Meraki Managed Services | G4: Software / Configuration | H4: Guwahati | I4: Q5AA-RM28-C2R8 | J4: Q5AA-RM28-C2R8 | K4: NA | L4: AP | M4: JFL-Guwahati-SSC-AP-03 | N4: CW9162I | O4: MR 32.1.7 | Q4: Non-Core | R4: Closed | S4: Client Side Activity | T4: Client Side Activity | U4: AP firmware activity going on due to that AP went down, So now firmware has been upgraded successfully and AP came online. | V4: 46119.88 | W4: 46119.978 | X4: 141.38 | Y4: 46119.88 | Z4: 0 | AA4: 30 | AB4: SLA Met | AC4: 46119.881 | AD4: 46119.975 | AE4: 135.13 | AF4: 6.25 | AG4: 120 | AH4: SLA Met | AJ4: 129600 | AK4: =AJ4-AF4 -> 129593.75 | AL4: =AK4/AJ4*100 -> 99.995177 | AM4: =AJ4-AE4 -> 129464.87 | AN4: =AM4/AJ4*100 -> 99.895733
A5: Jubilant Foodworks Ltd (JFL) | B5: Alert | C5: Kartik Choudhary | D5: PRO/INC/41635 | E5: new dhcp server detected | F5: Meraki Managed Services | G5: Software / Configuration | H5: Nagpur | I5: Q5JJ-68KZ-MXAS | J5: Q5JJ-68KZ-MXAS | K5: RACK 1 | L5: SW | M5: JFL-NAG-SSC-SW01 | N5: C9300L-48P-4X | O5: cs-17-2-2 | Q5: Non-Core | R5: Closed | S5: Third Party Device issue | T5: observation with customer, Customer reply awaiting. | U5: new DHCP server blocked | V5: 46120.237 | W5: 46125.506 | X5: 7587.22 | Y5: 46120.237 | Z5: 0.02 | AA5: 30 | AB5: SLA Met | AC5: 46120.242 | AD5: 46125.505 | AE5: 7578.73 | AF5: 8.48 | AG5: 120 | AH5: SLA Met | AJ5: 129600 | AK5: =AJ5-AF5 -> 129591.52 | AL5: =AK5/AJ5*100 -> 99.993457 | AM5: =AJ5-AE5 -> 122021.27 | AN5: =AM5/AJ5*100 -> 94.152215
A6: Jubilant Foodworks Ltd (JFL) | B6: Alert | C6: Dheerendra Maurya | D6: PRO/INC/41650 | E6: aps went down | F6: Meraki Managed Services | G6: Software / Configuration | H6: Bangalore | I6: Q3AC-9EFV-95CH | J6: Q3AC-9EFV-95CH | K6: NA | L6: AP | M6: 2F-AP20-R4-SW2-45P | N6: MR46 | O6: wireless-31-1-8 | Q6: Non-Core | R6: Closed | S6: Device Power Issues | T6: POWER ISSUE | U6: AP went down due to power issue | V6: 46120.542 | W6: 46120.596 | X6: 76.9 | Y6: 46120.542 | Z6: 0.02 | AA6: 30 | AB6: SLA Met | AC6: 46120.545 | AD6: 46120.595 | AE6: 71.62 | AF6: 5.28 | AG6: 120 | AH6: SLA Met | AJ6: 129600 | AK6: =AJ6-AF6 -> 129594.72 | AL6: =AK6/AJ6*100 -> 99.995926 | AM6: =AJ6-AE6 -> 129528.38 | AN6: =AM6/AJ6*100 -> 99.944738
A7: Jubilant Foodworks Ltd (JFL) | B7: Alert | C7: Dheerendra Maurya | D7: PRO/INC/41649 | E7: aps went down | F7: Meraki Managed Services | G7: Software / Configuration | H7: Bangalore | I7: Q3AC-C4P4-JNC9 | J7: Q3AC-C4P4-JNC9 | K7: NA | L7: AP | M7: 2F-AP18-R4-SW2-8P | N7: MR46 | O7: wireless-31-1-8 | Q7: Non-Core | R7: Closed | S7: Device Power Issues | T7: POWER ISSUE | U7: AP went down due to power issue | V7: 46120.542 | W7: 46120.594 | X7: 74.9 | Y7: 46120.542 | Z7: 0 | AA7: 30 | AB7: SLA Met | AC7: 46120.546 | AD7: 46120.594 | AE7: 69.08 | AF7: 5.82 | AG7: 120 | AH7: SLA Met | AJ7: 129600 | AK7: =AJ7-AF7 -> 129594.18 | AL7: =AK7/AJ7*100 -> 99.995509 | AM7: =AJ7-AE7 -> 129530.92 | AN7: =AM7/AJ7*100 -> 99.946698
A8: Jubilant Foodworks Ltd (JFL) | B8: Alert | C8: Dheerendra Maurya | D8: PRO/INC/41651 | E8: aps went down | F8: Meraki Managed Services | G8: Software / Configuration | H8: Bangalore | I8: Q3AC-PGZ6-YM5F | J8: Q3AC-PGZ6-YM5F | K8: NA | L8: AP | M8: 2F-AP12-R5-SW2-4P | N8: MR46 | O8: wireless-31-1-8 | Q8: Non-Core | R8: Closed | S8: Device Power Issues | T8: POWER ISSUE | U8: AP went down due to power issue | V8: 46120.542 | W8: 46120.597 | X8: 78.85 | Y8: 46120.542 | Z8: 0 | AA8: 30 | AB8: SLA Met | AC8: 46120.546 | AD8: 46120.596 | AE8: 72.12 | AF8: 6.73 | AG8: 120 | AH8: SLA Met | AJ8: 129600 | AK8: =AJ8-AF8 -> 129593.27 | AL8: =AK8/AJ8*100 -> 99.994807 | AM8: =AJ8-AE8 -> 129527.88 | AN8: =AM8/AJ8*100 -> 99.944352
A9: Jubilant Foodworks Ltd (JFL) | B9: Alert | C9: Aneesh P S | D9: PRO/INC/41652 | E9: switches went down | F9: Meraki Managed Services | G9: Software / Configuration | H9: Bangalore | I9: Q2QW-CTCG-QKDE | J9: Q2QW-CTCG-QKDE | K9: 2F-R5 | L9: SW | M9: 2F-R5-SW1 | N9: MS250-48FP | O9: switch-17-1-4 | Q9: Core | R9: Closed | S9: Device Power Issues | T9: POWER ISSUE | U9: Device Power issues | V9: 46120.544 | W9: 46120.609 | X9: 93.73 | Y9: 46120.544 | Z9: 0.02 | AA9: 30 | AB9: SLA Met | AC9: 46120.547 | AD9: 46120.602 | AE9: 79.48 | AF9: 14.25 | AG9: 120 | AH9: SLA Met | AJ9: 129600 | AK9: =AJ9-AF9 -> 129585.75 | AL9: =AK9/AJ9*100 -> 99.989005 | AM9: =AJ9-AE9 -> 129520.52 | AN9: =AM9/AJ9*100 -> 99.938673
A10: Jubilant Foodworks Ltd (JFL) | B10: Alert | C10: Dheerendra Maurya | D10: PRO/INC/41653 | E10: switches went down | F10: Meraki Managed Services | G10: Software / Configuration | H10: Bangalore | I10: Q2QW-CTMF-ZXMF | J10: Q2QW-CTMF-ZXMF | K10: 2F-R5 | L10: SW | M10: 2F-R5-SW2 | N10: MS250-48FP | O10: switch-17-2-2 | Q10: Core | R10: Closed | S10: Device Power Issues | T10: POWER ISSUE | U10: Switch went down due to power issue | V10: 46120.544 | W10: 46120.599 | X10: 78.68 | Y10: 46120.544 | Z10: 0 | AA10: 30 | AB10: SLA Met | AC10: 46120.548 | AD10: 46120.598 | AE10: 72.73 | AF10: 5.95 | AG10: 120 | AH10: SLA Met | AJ10: 129600 | AK10: =AJ10-AF10 -> 129594.05 | AL10: =AK10/AJ10*100 -> 99.995409 | AM10: =AJ10-AE10 -> 129527.27 | AN10: =AM10/AJ10*100 -> 99.943881
A11: Jubilant Foodworks Ltd (JFL) | B11: Alert | C11: Dheerendra Maurya | D11: PRO/INC/41657 | E11: aps went down | F11: Meraki Managed Services | G11: Software / Configuration | H11: Bangalore | I11: Q3AC-JN66-PSGV | J11: Q3AC-JN66-PSGV | K11: NA | L11: AP | M11: 2F-AP04-R4-SW3-24P | N11: MR46 | O11: wireless-31-1-8 | Q11: Non-Core | R11: Closed | S11: Device Power Issues | T11: Power issue | U11: AP WENT DOWN DUE TO POWER ISSUE | V11: 46120.64 | W11: 46120.699 | X11: 83.95 | Y11: 46120.64 | Z11: 0.02 | AA11: 30 | AB11: SLA Met | AC11: 46120.643 | AD11: 46120.698 | AE11: 79.28 | AF11: 4.67 | AG11: 120 | AH11: SLA Met | AJ11: 129600 | AK11: =AJ11-AF11 -> 129595.33 | AL11: =AK11/AJ11*100 -> 99.996397 | AM11: =AJ11-AE11 -> 129520.72 | AN11: =AM11/AJ11*100 -> 99.938827
A12: Jubilant Foodworks Ltd (JFL) | B12: Alert | C12: Dheerendra Maurya | D12: PRO/INC/41658 | E12: aps went down | F12: Meraki Managed Services | G12: Software / Configuration | H12: Bangalore | I12: Q3AC-9EFV-95CH | J12: Q3AC-9EFV-95CH | K12: NA | L12: AP | M12: 2F-AP20-R4-SW2-45P | N12: MR46 | O12: wireless-31-1-8 | Q12: Non-Core | R12: Closed | S12: Device Power Issues | T12: power issue | U12: AP WENT DOWN DUE TO POWER ISSUE | V12: 46120.64 | W12: 46120.694 | X12: 77.93 | Y12: 46120.64 | Z12: 0 | AA12: 30 | AB12: SLA Met | AC12: 46120.645 | AD12: 46120.693 | AE12: 68.73 | AF12: 9.2 | AG12: 120 | AH12: SLA Met | AJ12: 129600 | AK12: =AJ12-AF12 -> 129590.8 | AL12: =AK12/AJ12*100 -> 99.992901 | AM12: =AJ12-AE12 -> 129531.27 | AN12: =AM12/AJ12*100 -> 99.946968
A13: Jubilant Foodworks Ltd (JFL) | B13: Alert | C13: Dheerendra Maurya | D13: PRO/INC/41659 | E13: switches went down | F13: Meraki Managed Services | G13: Software / Configuration | H13: Bangalore | I13: Q2QW-ARKH-HCRT | J13: Q2QW-ARKH-HCRT | K13: 2F-R4 | L13: SW | M13: 2F-R4-SW2 | N13: MS250-48FP | O13: switch-17-1-4 | Q13: Core | R13: Closed | S13: Device Power Issues | T13: power issue | U13: Switch went down due to power issue | V13: 46120.642 | W13: 46120.688 | X13: 67.07 | Y13: 46120.642 | Z13: 0.02 | AA13: 30 | AB13: SLA Met | AC13: 46120.644 | AD13: 46120.684 | AE13: 58.27 | AF13: 8.8 | AG13: 120 | AH13: SLA Met | AJ13: 129600 | AK13: =AJ13-AF13 -> 129591.2 | AL13: =AK13/AJ13*100 -> 99.99321 | AM13: =AJ13-AE13 -> 129541.73 | AN13: =AM13/AJ13*100 -> 99.955039
A14: Jubilant Foodworks Ltd (JFL) | B14: Alert | C14: Dheerendra Maurya | D14: PRO/INC/41660 | E14: aps went down | F14: Meraki Managed Services | G14: Software / Configuration | H14: Bangalore | I14: Q3AC-PGZ6-YM5F | J14: Q3AC-PGZ6-YM5F | K14: NA | L14: AP | M14: 2F-AP12-R5-SW2-4P | N14: MR46 | O14: wireless-31-1-8 | Q14: Non-Core | R14: Closed | S14: Device Power Issues | T14: power issue | U14: AP went down due to power issue | V14: 46120.669 | W14: 46120.713 | X14: 62.68 | Y14: 46120.669 | Z14: 0.02 | AA14: 30 | AB14: SLA Met | AC14: 46120.678 | AD14: 46120.711 | AE14: 47.17 | AF14: 15.52 | AG14: 120 | AH14: SLA Met | AJ14: 129600 | AK14: =AJ14-AF14 -> 129584.48 | AL14: =AK14/AJ14*100 -> 99.988025 | AM14: =AJ14-AE14 -> 129552.83 | AN14: =AM14/AJ14*100 -> 99.963603
A15: Jubilant Foodworks Ltd (JFL) | B15: Alert | C15: Dheerendra Maurya | D15: PRO/INC/41661 | E15: aps went down | F15: Meraki Managed Services | G15: Software / Configuration | H15: Bangalore | I15: Q3AC-C4P4-JNC9 | J15: Q3AC-C4P4-JNC9 | K15: NA | L15: AP | M15: 2F-AP18-R4-SW2-8P | N15: MR46 | O15: wireless-31-1-8 | Q15: Non-Core | R15: Closed | S15: Device Power Issues | T15: power issue | U15: AP WENT DOWN DUE TO POWER ISSUE | V15: 46120.669 | W15: 46120.711 | X15: 60.68 | Y15: 46120.669 | Z15: 0.02 | AA15: 30 | AB15: SLA Met | AC15: 46120.679 | AD15: 46120.71 | AE15: 45 | AF15: 15.68 | AG15: 120 | AH15: SLA Met | AJ15: 129600 | AK15: =AJ15-AF15 -> 129584.32 | AL15: =AK15/AJ15*100 -> 99.987901 | AM15: =AJ15-AE15 -> 129555 | AN15: =AM15/AJ15*100 -> 99.965278
... A33: Jubilant Foodworks Ltd (JFL) | B33: Alert | C33: John Ashis Roy | D33: PRO/INC/43795 | E33: switches went down | F33: Meraki Managed Services | G33: Software / Configuration | H33: Bangalore | I33: Q2QW-CAJU-QVKD | J33: Q2QW-CAJU-QVKD | K33: GF-ETP | L33: SW | M33: GF-ETP-SW1 | N33: MS250-48FP | O33: switch-17-1-4 | Q33: Core | R33: Closed | S33: Device Power Issues | T33: Power Issue | U33: Resolved | V33: 46138.66 | W33: 46141.5 | X33: 4089.13 | Y33: 46138.66 | Z33: 0.02 | AA33: 30 | AB33: SLA Met | AC33: 46138.662 | AD33: 46141.504 | AE33: 4092 | AF33: -2.87 | AG33: 120 | AH33: SLA Met | AJ33: 129600 | AK33: =AJ33-AF33 -> 129602.87 | AL33: =AK33/AJ33*100 -> 100.00221 | AM33: =AJ33-AE33 -> 125508 | AN33: =AM33/AJ33*100 -> 96.842593
A34: Jubilant Foodworks Ltd (JFL) | B34: Alert | C34: Dheerendra Maurya | D34: PRO/INC/44364 | E34: Need to Enable VLan 100 - SEC-CAB-SW1-Port 31 | F34: Meraki Managed Services | G34: Change Request | H34: Bangalore | J34: Q2QW-FCJL-LJS8 | K34: SEC-CAB | L34: SW | M34: SEC-CAB-SW1 | N34: MS250-48FP | O34: switch-17-2-2 | Q34: P4 | R34: Closed | S34: New Configuration | U34: Enabled sec rack port 31 under vlan 100 | V34: 46139.691 | W34: 46139.706 | X34: 21.38 | Y34: 46139.691 | Z34: 0.02 | AA34: 30 | AB34: SLA Met | AE34: 0 | AF34: 21.38 | AG34: 2880 | AH34: SLA Met | AJ34: 129600 | AK34: =AJ34-AF34 -> 129578.62 | AL34: =AK34/AJ34*100 -> 99.983503 | AM34: =AJ34-AE34 -> 129600 | AN34: =AM34/AJ34*100 -> 100
A35: Jubilant Foodworks Ltd (JFL) | B35: Alert | C35: Shresth Kushwaha | D35: PRO/INC/44366 | E35: Need to Enable VLan 100 - SEC-CAB-SW2-Port 47 | F35: Meraki Managed Services | G35: Change Request | H35: Bangalore | J35: Q2QW-FCH3-EMVG | K35: SEC-CAB | L35: SW | M35: SEC-CAB-SW2 | N35: MS250-48FP | O35: switch-17-2-2 | Q35: P4 | R35: Closed | S35: New Configuration | U35: Enabled VLan 100 - SEC-CAB-SW2-Port 47 | V35: 46139.7 | W35: 46139.71 | X35: 15.63 | Y35: 46139.7 | Z35: 0.02 | AA35: 30 | AB35: SLA Met | AE35: 0 | AF35: 15.63 | AG35: 2880 | AH35: SLA Met | AJ35: 129600 | AK35: =AJ35-AF35 -> 129584.37 | AL35: =AK35/AJ35*100 -> 99.98794 | AM35: =AJ35-AE35 -> 129600 | AN35: =AM35/AJ35*100 -> 100
A36: Jubilant Foodworks Ltd (JFL) | B36: Alert | C36: Kartik Choudhary | D36: PRO/INC/44555 | E36: aps went down | F36: Meraki Managed Services | G36: Software / Configuration | H36: Greater Noida | I36: Q5AA-J9A9-ZJ2B | J36: Q5AA-J9A9-ZJ2B | K36: NA | L36: AP | M36: JFL-GNSC-AP30 | N36: CW9162I | O36: wireless-31-1-7 | Q36: Non-Core | R36: Closed | S36: Device Power Issues | U36: Power issue | V36: 46142.54 | W36: 46142.545 | X36: 7.57 | Y36: 46142.54 | Z36: 0.02 | AA36: 30 | AB36: SLA Met | AE36: 0 | AF36: 7.57 | AG36: 120 | AH36: SLA Met | AJ36: 129600 | AK36: =AJ36-AF36 -> 129592.43 | AL36: =AK36/AJ36*100 -> 99.994159 | AM36: =AJ36-AE36 -> 129600 | AN36: =AM36/AJ36*100 -> 100
A37: Jubilant Foodworks Ltd (JFL) | B37: Alert | C37: Kartik Choudhary | D37: PRO/INC/44676 | E37: new dhcp server detected | F37: Meraki Managed Services | G37: Software / Configuration | H37: Nagpur | I37: Q5JJ-68KZ-MXAS | J37: Q5JJ-68KZ-MXAS | K37: RACK 1 | L37: SW | M37: JFL-NAG-SSC-SW01 | N37: C9300L-48P-4X | O37: cs-17-2-2 | Q37: Non-Core | R37: Closed | S37: Third Party Device issue | T37: Information has been shared with the customer. We are currently awaiting their response to proceed further. | U37: We have blocked the new DHCP server as per customer confirmation. | V37: 46144.804 | W37: 46144.835 | X37: 44.68 | Y37: 46144.804 | Z37: 0.02 | AA37: 30 | AB37: SLA Met | AC37: 46144.807 | AD37: 46144.833 | AE37: 37.25 | AF37: 7.43 | AG37: 120 | AH37: SLA Met | AJ37: 129600 | AK37: =AJ37-AF37 -> 129592.57 | AL37: =AK37/AJ37*100 -> 99.994267 | AM37: =AJ37-AE37 -> 129562.75 | AN37: =AM37/AJ37*100 -> 99.971258
A38: Jubilant Foodworks Ltd (JFL) | B38: Alert | C38: Shresth Kushwaha | D38: PRO/INC/44719 | E38: aps went down | F38: Meraki Managed Services | G38: Software / Configuration | H38: Greater Noida | I38: Q3KG-JH9T-FL7Z | J38: Q3KG-JH9T-FL7Z | K38: NA | L38: AP | M38: JFL-GNSC-AP48 | N38: MR86 | O38: wireless-31-1-7 | Q38: Non-Core | R38: Closed | S38: Device Power Issues | T38: Power issue | U38: POWER ISSUE | V38: 46146.091 | W38: 46155.856 | X38: 14060.8 | Y38: 46146.091 | Z38: 0 | AA38: 30 | AB38: SLA Met | AC38: 46146.093 | AD38: 46155.854 | AE38: 14055.38 | AF38: 5.42 | AG38: 120 | AH38: SLA Met | AJ38: 129600 | AK38: =AJ38-AF38 -> 129594.58 | AL38: =AK38/AJ38*100 -> 99.995818 | AM38: =AJ38-AE38 -> 115544.62 | AN38: =AM38/AJ38*100 -> 89.154799
A39: Jubilant Foodworks Ltd (JFL) | B39: Alert | C39: Shresth Kushwaha | D39: PRO/INC/44727 | E39: aps went down | F39: Meraki Managed Services | G39: Software / Configuration | H39: Greater Noida | I39: Q3KG-JH9T-FL7Z | J39: Q3KG-JH9T-FL7Z | K39: NA | L39: AP | M39: JFL-GNSC-AP48 | N39: MR86 | O39: wireless-31-1-7 | Q39: Non-Core | R39: Closed | S39: Device Power Issues | T39: Power issue | U39: POWER ISSUE | V39: 46146.172 | W39: 46155.857 | X39: 13946.2 | Y39: 46146.172 | Z39: 0 | AA39: 30 | AB39: SLA Met | AC39: 46146.173 | AD39: 46155.854 | AE39: 13940.92 | AF39: 5.28 | AG39: 120 | AH39: SLA Met | AJ39: 129600 | AK39: =AJ39-AF39 -> 129594.72 | AL39: =AK39/AJ39*100 -> 99.995926 | AM39: =AJ39-AE39 -> 115659.08 | AN39: =AM39/AJ39*100 -> 89.243117
A40: Jubilant Foodworks Ltd (JFL) | B40: Alert | C40: Aneesh P S | D40: PRO/INC/44814 | E40: aps went down | F40: Meraki Managed Services | G40: Software / Configuration | H40: Bangalore | I40: Q5AE-KNH9-5GV8 | J40: Q5AE-KNH9-5GV8 | K40: NA | L40: AP | M40: GF-AP01-ETP-SW1-10P | N40: CW9166I | O40: wireless-31-1-8 | Q40: Non-Core | R40: Closed | S40: Device Power Issues | T40: Device Power issues | U40: Device Power Issues | V40: 46147.482 | W40: 46147.499 | X40: 25.07 | Y40: 46147.482 | Z40: 0.02 | AA40: 30 | AB40: SLA Met | AC40: 46147.486 | AD40: 46147.497 | AE40: 16.27 | AF40: 8.8 | AG40: 120 | AH40: SLA Met | AJ40: 129600 | AK40: =AJ40-AF40 -> 129591.2 | AL40: =AK40/AJ40*100 -> 99.99321 | AM40: =AJ40-AE40 -> 129583.73 | AN40: =AM40/AJ40*100 -> 99.987446
A41: Jubilant Foodworks Ltd (JFL) | B41: Alert | C41: Aneesh P S | D41: PRO/INC/44815 | E41: switches went down | F41: Meraki Managed Services | G41: Software / Configuration | H41: Bangalore | I41: Q2QW-CAJU-QVKD | J41: Q2QW-CAJU-QVKD | K41: GF-ETP | L41: SW | M41: GF-ETP-SW1 | N41: MS250-48FP | O41: switch-17-1-4 | Q41: Core | R41: Closed | S41: Device Power Issues | T41: Device Power issues | U41: Device Power Issues | V41: 46147.483 | W41: 46147.499 | X41: 21.95 | Y41: 46147.483 | Z41: 0 | AA41: 30 | AB41: SLA Met | AC41: 46147.486 | AD41: 46147.497 | AE41: 16.05 | AF41: 5.9 | AG41: 120 | AH41: SLA Met | AJ41: 129600 | AK41: =AJ41-AF41 -> 129594.1 | AL41: =AK41/AJ41*100 -> 99.995448 | AM41: =AJ41-AE41 -> 129583.95 | AN41: =AM41/AJ41*100 -> 99.987616
A42: Jubilant Foodworks Ltd (JFL) | B42: Alert | C42: Dheerendra Maurya | D42: PRO/INC/44824 | E42: new dhcp server detected | F42: Meraki Managed Services | G42: Software / Configuration | H42: Nagpur | I42: Q5JJ-68KZ-MXAS | J42: Q5JJ-68KZ-MXAS | K42: RACK 1 | L42: SW | M42: JFL-NAG-SSC-SW01 | N42: C9300L-48P-4X | O42: cs-17-2-2 | Q42: Non-Core | R42: Closed | S42: Third Party Device issue | T42: DHCP New device detected | U42: We have blocked Mac address.New dhcp server detected issue has been resolved. . now closed the case | V42: 46147.584 | W42: 46147.821 | X42: 341.62 | Y42: 46147.584 | Z42: 0.02 | AA42: 30 | AB42: SLA Met | AC42: 46147.602 | AD42: 46147.818 | AE42: 311.2 | AF42: 30.42 | AG42: 120 | AH42: SLA Met | AJ42: 129600 | AK42: =AJ42-AF42 -> 129569.58 | AL42: =AK42/AJ42*100 -> 99.976528 | AM42: =AJ42-AE42 -> 129288.8 | AN42: =AM42/AJ42*100 -> 99.759877
A43: Jubilant Foodworks Ltd (JFL) | B43: Alert | C43: Abhishek Satish Pawar | D43: PRO/INC/44850 | E43: aps went down | F43: Meraki Managed Services | G43: Software / Configuration | H43: Bangalore | I43: Q3AC-Y2HS-V29M | J43: Q3AC-Y2HS-V29M | K43: NA | L43: AP | M43: 1F-AP26-R5-SW02-34P | N43: MR46 | O43: wireless-31-1-8 | Q43: Non-Core | R43: Closed | S43: Device Power Issues | T43: power issue | U43: resolved | V43: 46147.981 | W43: 46156.503 | X43: 12272.37 | Y43: 46147.981 | Z43: 0.02 | AA43: 30 | AB43: SLA Met | AC43: 46147.982 | AD43: 46156.501 | AE43: 12266.73 | AF43: 5.63 | AG43: 120 | AH43: SLA Met | AJ43: 129600 | AK43: =AJ43-AF43 -> 129594.37 | AL43: =AK43/AJ43*100 -> 99.995656 | AM43: =AJ43-AE43 -> 117333.27 | AN43: =AM43/AJ43*100 -> 90.534931
A44: Jubilant Foodworks Ltd (JFL) | B44: Alert | C44: Abhishek Satish Pawar | D44: PRO/INC/44851 | E44: aps went down | F44: Meraki Managed Services | G44: Software / Configuration | H44: Bangalore | I44: Q3AC-RQJS-FY3M | J44: Q3AC-RQJS-FY3M | K44: NA | L44: AP | M44: 1F-AP14-R04-SW02-11P | N44: MR46 | O44: wireless-31-1-8 | Q44: Non-Core | R44: Closed | S44: Device Power Issues | T44: power issue | U44: resolved | V44: 46147.981 | W44: 46156.503 | X44: 12272.32 | Y44: 46147.981 | Z44: 0 | AA44: 30 | AB44: SLA Met | AC44: 46147.984 | AD44: 46156.502 | AE44: 12266.82 | AF44: 5.5 | AG44: 120 | AH44: SLA Met | AJ44: 129600 | AK44: =AJ44-AF44 -> 129594.5 | AL44: =AK44/AJ44*100 -> 99.995756 | AM44: =AJ44-AE44 -> 117333.18 | AN44: =AM44/AJ44*100 -> 90.534861
A45: Jubilant Foodworks Ltd (JFL) | B45: Alert | C45: Abhishek Satish Pawar | D45: PRO/INC/44853 | E45: aps went down | F45: Meraki Managed Services | G45: Software / Configuration | H45: Bangalore | I45: Q3AC-DZAX-3FNP | J45: Q3AC-DZAX-3FNP | K45: NA | L45: AP | M45: 1F-AP13-R04-SW02-13P | N45: MR46 | O45: wireless-31-1-8 | Q45: Non-Core | R45: Closed | S45: Device Power Issues | T45: power issue | U45: resolved | V45: 46147.981 | W45: 46156.505 | X45: 12274.23 | Y45: 46147.981 | Z45: 0.02 | AA45: 30 | AB45: SLA Met | AC45: 46147.985 | AD45: 46156.504 | AE45: 12267.5 | AF45: 6.73 | AG45: 120 | AH45: SLA Met | AJ45: 129600 | AK45: =AJ45-AF45 -> 129593.27 | AL45: =AK45/AJ45*100 -> 99.994807 | AM45: =AJ45-AE45 -> 117332.5 | AN45: =AM45/AJ45*100 -> 90.534336
A46: Jubilant Foodworks Ltd (JFL) | B46: Alert | C46: Abhishek Satish Pawar | D46: PRO/INC/44852 | E46: aps went down | F46: Meraki Managed Services | G46: Software / Configuration | H46: Bangalore | I46: Q3AC-E8LA-PVD4 | J46: Q3AC-E8LA-PVD4 | K46: NA | L46: AP | M46: 1F-AP10-R05-SW02-44P | N46: MR46 | O46: wireless-31-1-8 | Q46: Non-Core | R46: Closed | S46: Device Power Issues | T46: power issue | U46: resolved | V46: 46147.981 | W46: 46156.506 | X46: 12275.23 | Y46: 46147.981 | Z46: 0 | AA46: 30 | AB46: SLA Met | AC46: 46147.984 | AD46: 46156.505 | AE46: 12269.57 | AF46: 5.67 | AG46: 120 | AH46: SLA Met | AJ46: 129600 | AK46: =AJ46-AF46 -> 129594.33 | AL46: =AK46/AJ46*100 -> 99.995625 | AM46: =AJ46-AE46 -> 117330.43 | AN46: =AM46/AJ46*100 -> 90.532739
A47: Jubilant Foodworks Ltd (JFL) | B47: Alert | C47: Abhishek Satish Pawar | D47: PRO/INC/44988 | E47: switches went down | F47: Meraki Managed Services | G47: Software / Configuration | H47: Greater Noida | I47: Q5TN-NF5F-N32X | J47: Q5TN-NF5F-N32X | K47: Core | L47: SW | M47: JFL-GNSC-CORE-SW-ST-01 [1] | N47: C9300X-24Y | O47: ios-xe-17-15-4 | Q47: Core | R47: Closed | S47: Device Power Issues | T47: power issue | U47: After restore issue has been resolved | V47: 46150.096 | W47: 46153.354 | X47: 4691.15 | Y47: 46150.096 | Z47: 0.02 | AA47: 30 | AB47: SLA Met | AC47: 46150.098 | AD47: 46153.353 | AE47: 4687.18 | AF47: 3.97 | AG47: 120 | AH47: SLA Met | AJ47: 129600 | AK47: =AJ47-AF47 -> 129596.03 | AL47: =AK47/AJ47*100 -> 99.996937 | AM47: =AJ47-AE47 -> 124912.82 | AN47: =AM47/AJ47*100 -> 96.383349
A48: Jubilant Foodworks Ltd (JFL) | B48: Alert | C48: Aneesh P S | D48: PRO/INC/45099 | E48: aps went down | F48: Meraki Managed Services | G48: Software / Configuration | H48: Mohali | I48: Q5AR-A7VQ-MZJM | J48: Q5AR-A7VQ-MZJM | K48: NA | L48: AP | M48: JFL-Mohali-SCC-AP13 | N48: CW9166I | O48: wireless-31-1-7 | Q48: Non-Core | R48: Closed | S48: Device Power Issues | T48: Power Issue | U48: Device Power Issues | V48: 46152.438 | W48: 46153.375 | X48: 1349.37 | Y48: 46152.438 | Z48: 0.02 | AA48: 30 | AB48: SLA Met | AC48: 46152.445 | AD48: 46153.337 | AE48: 1284.77 | AF48: 64.6 | AG48: 120 | AH48: SLA Met | AJ48: 129600 | AK48: =AJ48-AF48 -> 129535.4 | AL48: =AK48/AJ48*100 -> 99.950154 | AM48: =AJ48-AE48 -> 128315.23 | AN48: =AM48/AJ48*100 -> 99.008665
A49: Jubilant Foodworks Ltd (JFL) | B49: Alert | C49: Aneesh P S | D49: PRO/INC/45327 | E49: aps went down | F49: Meraki Managed Services | G49: Software / Configuration | H49: Greater Noida | I49: Q3KG-JH9T-FL7Z | J49: Q3KG-JH9T-FL7Z | K49: NA | L49: AP | M49: JFL-GNSC-AP48 | N49: MR86 | O49: wireless-31-1-7 | Q49: Non-Core | R49: Closed | S49: Device Power Issues | T49: POWER ISSUE | U49: Device power issues | V49: 46154.933 | W49: 46155.017 | X49: 120.32 | Y49: 46154.933 | Z49: 0.02 | AA49: 30 | AB49: SLA Met | AC49: 46154.937 | AD49: 46155.013 | AE49: 109.78 | AF49: 10.53 | AG49: 120 | AH49: SLA Met | AJ49: 129600 | AK49: =AJ49-AF49 -> 129589.47 | AL49: =AK49/AJ49*100 -> 99.991875 | AM49: =AJ49-AE49 -> 129490.22 | AN49: =AM49/AJ49*100 -> 99.915293
A50: Jubilant Foodworks Ltd (JFL) | B50: Email | C50: Kartik Choudhary | D50: PRO/INC/45342 | E50: Request to Whitelist New MAC Address for Mohali SCC Desktop | F50: Meraki Managed Services | G50: Change Request | H50: Mohali | I50: Q5JJ-3TZH-2HV5 | J50: Q5JJ-3TZH-2HV5 | K50: CORE | L50: SW | M50: JFL-MOHALI-CORE-01 | N50: C9300L-48P-4X | O50: cs-17-2-1 | Q50: P4 | R50: Closed | S50: New Configuration | U50: Required changes has been made successfully and same has been confirmed with customer. | V50: 46155.588 | W50: 46155.64 | X50: 74.45 | Y50: 46155.588 | Z50: 0 | AA50: 30 | AB50: SLA Met | AE50: 0 | AF50: 74.45 | AG50: 2880 | AH50: SLA Met | AJ50: 129600 | AK50: =AJ50-AF50 -> 129525.55 | AL50: =AK50/AJ50*100 -> 99.942554 | AM50: =AJ50-AE50 -> 129600 | AN50: =AM50/AJ50*100 -> 100
A51: Jubilant Foodworks Ltd (JFL) | B51: Alert | C51: Aneesh P S | D51: PRO/INC/45359 | E51: aps went down | F51: Meraki Managed Services | G51: Software / Configuration | H51: Greater Noida | I51: Q3KG-Y2PU-4DWW | J51: Q3KG-Y2PU-4DWW | K51: NA | L51: AP | M51: JFL-GNSC-AP55 | N51: MR86 | O51: wireless-31-1-7 | Q51: Non-Core | R51: Closed | S51: Device Power Issues | T51: Device Power Issues | U51: Device Power Issue | V51: 46156.274 | W51: 46156.292 | X51: 26.03 | Y51: 46156.274 | Z51: 0.02 | AA51: 30 | AB51: SLA Met | AC51: 46156.28 | AD51: 46156.281 | AE51: 1.47 | AF51: 24.57 | AG51: 120 | AH51: SLA Met | AJ51: 129600 | AK51: =AJ51-AF51 -> 129575.43 | AL51: =AK51/AJ51*100 -> 99.981042 | AM51: =AJ51-AE51 -> 129598.53 | AN51: =AM51/AJ51*100 -> 99.998866
A52: Jubilant Foodworks Ltd (JFL) | B52: Alert | C52: Dharmendra Bhadoriya | D52: PRO/INC/45363 | E52: aps went down | F52: Meraki Managed Services | G52: Software / Configuration | H52: Greater Noida | I52: Q3KG-GWW5-CHJC | J52: Q3KG-GWW5-CHJC | K52: NA | L52: AP | M52: JFL-GNSC-AP52 | N52: MR86 | O52: wireless-31-1-7 | Q52: Non-Core | R52: Closed | S52: Device Power Issues | T52: Power Issue | U52: After restore issue has been resolved | V52: 46156.364 | W52: 46168.455 | X52: 17410.85 | Y52: 46156.364 | Z52: 0.02 | AA52: 30 | AB52: SLA Met | AC52: 46156.368 | AD52: 46168.451 | AE52: 17399.63 | AF52: 11.22 | AG52: 120 | AH52: SLA Met | AJ52: 129600 | AK52: =AJ52-AF52 -> 129588.78 | AL52: =AK52/AJ52*100 -> 99.991343 | AM52: =AJ52-AE52 -> 112200.37 | AN52: =AM52/AJ52*100 -> 86.57436
A53: Jubilant Foodworks Ltd (JFL) | B53: Alert | C53: Arvind Kumar Arya | D53: PRO/INC/45367 | E53: aps went down | F53: Meraki Managed Services | G53: Software / Configuration | H53: Greater Noida | I53: Q3KG-GWW5-CHJC | J53: Q3KG-GWW5-CHJC | K53: NA | L53: AP | M53: JFL-GNSC-AP52 | N53: MR86 | O53: wireless-31-1-7 | Q53: Non-Core | R53: Closed | S53: Device Power Issues | T53: ISP issue or Power issue | U53: Power issue | V53: 46156.393 | W53: 46156.675 | X53: 406.43 | Y53: 46156.393 | Z53: 0 | AA53: 30 | AB53: SLA Met | AC53: 46156.429 | AD53: 46156.674 | AE53: 353.43 | AF53: 53 | AG53: 120 | AH53: SLA Met | AJ53: 129600 | AK53: =AJ53-AF53 -> 129547 | AL53: =AK53/AJ53*100 -> 99.959105 | AM53: =AJ53-AE53 -> 129246.57 | AN53: =AM53/AJ53*100 -> 99.727292
A54: Jubilant Foodworks Ltd (JFL) | B54: Alert | C54: Dharmendra Bhadoriya | D54: PRO/INC/45370 | E54: aps went down | F54: Meraki Managed Services | G54: Software / Configuration | H54: Greater Noida | I54: Q3KG-GWW5-CHJC | J54: Q3KG-GWW5-CHJC | K54: NA | L54: AP | M54: JFL-GNSC-AP52 | N54: MR86 | O54: wireless-31-1-7 | Q54: Non-Core | R54: Closed | S54: Device Power Issues | T54: Power Issue | U54: After restore issue has been resolved | V54: 46156.431 | W54: 46168.456 | X54: 17316.23 | Y54: 46156.431 | Z54: 0.02 | AA54: 30 | AB54: SLA Met | AC54: 46156.433 | AD54: 46168.453 | AE54: 17309.37 | AF54: 6.87 | AG54: 120 | AH54: SLA Met | AJ54: 129600 | AK54: =AJ54-AF54 -> 129593.13 | AL54: =AK54/AJ54*100 -> 99.994699 | AM54: =AJ54-AE54 -> 112290.63 | AN54: =AM54/AJ54*100 -> 86.644005
A55: Jubilant Foodworks Ltd (JFL) | B55: Alert | C55: Arvind Kumar Arya | D55: PRO/INC/45373 | E55: aps went down | F55: Meraki Managed Services | G55: Software / Configuration | H55: Greater Noida | I55: Q3KG-XSEX-EG6A | J55: Q3KG-XSEX-EG6A | K55: NA | L55: AP | M55: JFL-GNSC-AP60 | N55: MR86 | O55: wireless-31-1-7 | Q55: Non-Core | R55: Closed | S55: Device Power Issues | T55: ISP issue or Power issue | U55: Power issue | V55: 46156.448 | W55: 46156.678 | X55: 330.68 | Y55: 46156.448 | Z55: 0 | AA55: 30 | AB55: SLA Met | AC55: 46156.464 | AD55: 46156.675 | AE55: 304.58 | AF55: 26.1 | AG55: 120 | AH55: SLA Met | AJ55: 129600 | AK55: =AJ55-AF55 -> 129573.9 | AL55: =AK55/AJ55*100 -> 99.979861 | AM55: =AJ55-AE55 -> 129295.42 | AN55: =AM55/AJ55*100 -> 99.764985
A56: Jubilant Foodworks Ltd (JFL) | B56: Alert | C56: Arvind Kumar Arya | D56: PRO/INC/45379 | E56: aps went down | F56: Meraki Managed Services | G56: Software / Configuration | H56: Greater Noida | I56: Q3KG-8U94-FMUC | J56: Q3KG-8U94-FMUC | K56: NA | L56: AP | M56: JFL-GNSC-AP56 | N56: MR86 | O56: wireless-31-1-7 | Q56: Non-Core | R56: Closed | S56: Device Power Issues | T56: isp issue or power issue | U56: Power issue | V56: 46156.453 | W56: 46156.679 | X56: 325.67 | Y56: 46156.453 | Z56: 0 | AA56: 30 | AB56: SLA Met | AC56: 46156.464 | AD56: 46156.679 | AE56: 308.37 | AF56: 17.3 | AG56: 120 | AH56: SLA Met | AJ56: 129600 | AK56: =AJ56-AF56 -> 129582.7 | AL56: =AK56/AJ56*100 -> 99.986651 | AM56: =AJ56-AE56 -> 129291.63 | AN56: =AM56/AJ56*100 -> 99.76206
A57: Jubilant Foodworks Ltd (JFL) | B57: Alert | C57: Arvind Kumar Arya | D57: PRO/INC/45381 | E57: aps went down | F57: Meraki Managed Services | G57: Software / Configuration | H57: Greater Noida | I57: Q3KG-Y2PU-4DWW | J57: Q3KG-Y2PU-4DWW | K57: NA | L57: AP | M57: JFL-GNSC-AP55 | N57: MR86 | O57: wireless-31-1-7 | Q57: Non-Core | R57: Closed | S57: Device Power Issues | T57: isp issue or power issue | U57: Power issue | V57: 46156.453 | W57: 46156.681 | X57: 327.52 | Y57: 46156.453 | Z57: 0.02 | AA57: 30 | AB57: SLA Met | AC57: 46156.465 | AD57: 46156.679 | AE57: 308.63 | AF57: 18.88 | AG57: 120 | AH57: SLA Met | AJ57: 129600 | AK57: =AJ57-AF57 -> 129581.12 | AL57: =AK57/AJ57*100 -> 99.985432 | AM57: =AJ57-AE57 -> 129291.37 | AN57: =AM57/AJ57*100 -> 99.76186
...

Sheet RCA
A3: Count of Device Type | B3: Column Labels | F3: Count of Device Type | G3: Column Labels | K3: Count of Device Type | L3: Column Labels | P3: Count of Device Type | Q3: Column Labels | U3: Count of Device Type | V3: Column Labels | Z3: Count of Device Type | AA3: Column Labels
A4: Row Labels | B4: AP | C4: SW | D4: Grand Total | F4: Row Labels | G4: AP | H4: SW | I4: Grand Total | K4: Row Labels | L4: AP | M4: SW | N4: Grand Total | P4: Row Labels | Q4: AP | R4: SW | S4: Grand Total | U4: Row Labels | V4: AP | W4: SW | X4: Grand Total | Z4: Row Labels | AA4: AP | AB4: Grand Total
A5: Bangalore | B5: 31 | C5: 39 | D5: 70 | F5: Greater Noida | G5: 169 | H5: 16 | I5: 185 | K5: Guwahati | L5: 10 | M5: 5 | N5: 15 | P5: Mohali | Q5: 33 | R5: 14 | S5: 47 | U5: Nagpur | V5: 5 | W5: 40 | X5: 45 | Z5: Noida | AA5: 1 | AB5: 1
A6: Device Power Issues | B6: 30 | C6: 28 | D6: 58 | F6: Device Power Issues | G6: 84 | H6: 4 | I6: 88 | K6: Device Power Issues | L6: 6 | M6: 4 | N6: 10 | P6: Device Power Issues | Q6: 24 | R6: 10 | S6: 34 | U6: Client Side Activity | V6: 4 | W6: 13 | X6: 17 | Z6: Hardware Component Failures | AA6: 1 | AB6: 1
A7: New Configuration | C7: 7 | D7: 7 | F7: Client Side Activity | G7: 78 | H7: 3 | I7: 81 | K7: Firmware or Software Bugs | L7: 3 | M7: 1 | N7: 4 | P7: Client Side Activity | Q7: 8 | R7: 2 | S7: 10 | U7: Third Party Device issue | W7: 13 | X7: 13 | Z7: Grand Total | AA7: 1 | AB7: 1
A8: Client Side Activity | B8: 1 | C8: 2 | D8: 3 | F8: New Configuration | H8: 7 | I8: 7 | K8: Client Side Activity | L8: 1 | N8: 1 | P8: New Configuration | Q8: 1 | R8: 1 | S8: 2 | U8: New Configuration | W8: 8 | X8: 8
A9: Others | C9: 2 | D9: 2 | F9: Device Boot Issues | G9: 5 | I9: 5 | K9: Grand Total | L9: 10 | M9: 5 | N9: 15 | P9: Others | R9: 1 | S9: 1 | U9: Others | W9: 2 | X9: 2
A10: Grand Total | B10: 31 | C10: 39 | D10: 70 | F10: Hardware Component Failures | G10: 2 | H10: 1 | I10: 3 | P10: Grand Total | Q10: 33 | R10: 14 | S10: 47 | U10: Configuration Errors | W10: 2 | X10: 2
F11: (blank) | H11: 1 | I11: 1 | U11: Customer Delays or Unresponsiveness | W11: 1 | X11: 1
F12: Grand Total | G12: 169 | H12: 16 | I12: 185 | U12: Device Power Issues | W12: 1 | X12: 1
U13: Device Boot Issues | V13: 1 | X13: 1
U14: Grand Total | V14: 5 | W14: 40 | X14: 45

Sheet Device Wise Uptime 
C2: Values
B3: Device Serial | C3: Sum of Proactive Uptime Mins | D3: Average of Proactive -Uptime% | E3: Sum of JFL -Uptime Mins | F3: Average of JFL -Uptime %
B4: FCW2110B25A | C4: 130297.08 | D4: 100.53787 | E4: 122093.45 | F4: 94.207909
B5: FCW2110B27N | C5: 129565.2 | D5: 99.973148 | E5: 119878.35 | F5: 92.498727
B6: FCW2211B365 | C6: 129556.87 | D6: 99.966721 | E6: 129441.58 | F6: 99.877762
B7: FGL2708LJWX | C7: 129570.53 | D7: 99.977261 | E7: 124120.9 | F7: 95.772299
B8: FJC290222SV | C8: 129581.97 | D8: 99.986088 | E8: 125174.43 | F8: 96.585208
B9: FOC2039V1JW | C9: 129359.55 | D9: 99.814468 | E9: 122211.85 | F9: 94.299267
B10: FOC2218T3Z8 | C10: 129579.57 | D10: 99.984236 | E10: 127847.35 | F10: 98.647647
B11: FVH2836L5EQ | C11: 259177.72 | D11: 99.991404 | E11: 256258.88 | F11: 98.865309
B12: FVH2903L6L7 | C12: 129579.3 | D12: 99.984028 | E12: 127191.17 | F12: 98.141335
B13: JIN2117106B | C13: 129382.23 | D13: 99.831968 | E13: 119801.4 | F13: 92.439352
B14: Q2DW-EM6A-8GPL | C14: 119297.6 | D14: 92.050617 | E14: 129600 | F14: 100
B15: Q2DW-FPMF-3AL6 | C15: 129590.12 | D15: 99.992377 | E15: 121537.02 | F15: 93.778565
... B155: Grand Total | C155: 47020508 | D155: 99.948363 | E155: 46005508 | F155: 97.790846

Sheet All Location 
A1: S.N | B1: Location | C1: Serial No. | D1: Device Type | E1: Average of Proactive -Uptime% | F1: Average of JFL -Uptime %
A2: 1 | B2: Guwahati | C2: Q3KG-ZJZJ-WWH5 | D2: AP | E2: =VLOOKUP(C2,'Device Wise Uptime '!B:D,3,0) -> 99.991485 | F2: =VLOOKUP(C2,'Device Wise Uptime '!B:F,5,0) -> 99.36016
A3: 2 | B3: Guwahati | C3: Q5AA-RM28-C2R8 | D3: AP | E3: =VLOOKUP(C3,'Device Wise Uptime '!B:D,3,0) -> 99.993573 | F3: =VLOOKUP(C3,'Device Wise Uptime '!B:F,5,0) -> 99.554988
A4: 3 | B4: Guwahati | C4: Q5AR-T7UY-LJRT | D4: AP | E4: 100 | F4: 100
A5: 4 | B5: Guwahati | C5: Q5JG-AQNW-P9FB | D5: SW | E5: =VLOOKUP(C5,'Device Wise Uptime '!B:D,3,0) -> 99.987369 | F5: =VLOOKUP(C5,'Device Wise Uptime '!B:F,5,0) -> 98.978071
A6: 5 | B6: Guwahati | C6: Q5JG-ECTW-5MN7 | D6: SW | E6: =VLOOKUP(C6,'Device Wise Uptime '!B:D,3,0) -> 99.993474 | F6: =VLOOKUP(C6,'Device Wise Uptime '!B:F,5,0) -> 99.121968
A7: 6 | B7: Mohali | C7: Q3KG-9RDD-U5HG | D7: AP | E7: =VLOOKUP(C7,'Device Wise Uptime '!B:D,3,0) -> 99.991992 | F7: =VLOOKUP(C7,'Device Wise Uptime '!B:F,5,0) -> 99.264852
A8: 7 | B8: Mohali | C8: Q3KG-LYY3-LR6R | D8: AP | E8: 100 | F8: 100
A9: 8 | B9: Mohali | C9: Q3KG-Y9ZZ-W8HK | D9: AP | E9: =VLOOKUP(C9,'Device Wise Uptime '!B:D,3,0) -> 99.989302 | F9: =VLOOKUP(C9,'Device Wise Uptime '!B:F,5,0) -> 99.328985
A10: 9 | B10: Mohali | C10: Q3LM-TGAF-Q97P | D10: AP | E10: =VLOOKUP(C10,'Device Wise Uptime '!B:D,3,0) -> 99.803547 | F10: =VLOOKUP(C10,'Device Wise Uptime '!B:F,5,0) -> 98.868315
A11: 10 | B11: Mohali | C11: Q3LP-2PSJ-6DLB | D11: AP | E11: =VLOOKUP(C11,'Device Wise Uptime '!B:D,3,0) -> 99.914029 | F11: =VLOOKUP(C11,'Device Wise Uptime '!B:F,5,0) -> 95.870848
A12: 11 | B12: Mohali | C12: Q5AA-43RJ-JQUD | D12: AP | E12: =VLOOKUP(C12,'Device Wise Uptime '!B:D,3,0) -> 99.427816 | F12: =VLOOKUP(C12,'Device Wise Uptime '!B:F,5,0) -> 98.805324
A13: 12 | B13: Mohali | C13: Q5AA-8PQC-7V98 | D13: AP | E13: =VLOOKUP(C13,'Device Wise Uptime '!B:D,3,0) -> 99.99233 | F13: =VLOOKUP(C13,'Device Wise Uptime '!B:F,5,0) -> 98.933086
A14: 13 | B14: Mohali | C14: Q5AA-E8FN-53RX | D14: AP | E14: =VLOOKUP(C14,'Device Wise Uptime '!B:D,3,0) -> 99.707859 | F14: =VLOOKUP(C14,'Device Wise Uptime '!B:F,5,0) -> 98.374745
A15: 14 | B15: Mohali | C15: Q5AA-GBHE-WVEQ | D15: AP | E15: 100 | F15: 100
A16: 15 | B16: Mohali | C16: Q5AA-GMN6-UE62 | D16: AP | E16: =VLOOKUP(C16,'Device Wise Uptime '!B:D,3,0) -> 99.993519 | F16: =VLOOKUP(C16,'Device Wise Uptime '!B:F,5,0) -> 99.771921
A17: 16 | B17: Mohali | C17: Q5AA-KHJW-U94C | D17: AP | E17: =VLOOKUP(C17,'Device Wise Uptime '!B:D,3,0) -> 99.712492 | F17: =VLOOKUP(C17,'Device Wise Uptime '!B:F,5,0) -> 99.137407
A18: 17 | B18: Mohali | C18: Q5AA-MHPW-2YA8 | D18: AP | E18: =VLOOKUP(C18,'Device Wise Uptime '!B:D,3,0) -> 99.994414 | F18: =VLOOKUP(C18,'Device Wise Uptime '!B:F,5,0) -> 98.670513
A19: 18 | B19: Mohali | C19: Q5AA-PHPN-4452 | D19: AP | E19: =VLOOKUP(C19,'Device Wise Uptime '!B:D,3,0) -> 99.995548 | F19: =VLOOKUP(C19,'Device Wise Uptime '!B:F,5,0) -> 99.559437
A20: 19 | B20: Mohali | C20: Q5AA-V3D8-DKEG | D20: AP | E20: =VLOOKUP(C20,'Device Wise Uptime '!B:D,3,0) -> 99.997056 | F20: =VLOOKUP(C20,'Device Wise Uptime '!B:F,5,0) -> 99.492928
A21: 20 | B21: Mohali | C21: Q5AR-56BZ-6TSR | D21: AP | E21: =VLOOKUP(C21,'Device Wise Uptime '!B:D,3,0) -> 99.706231 | F21: =VLOOKUP(C21,'Device Wise Uptime '!B:F,5,0) -> 99.327087
A22: 21 | B22: Mohali | C22: Q5AR-A7VQ-MZJM | D22: AP | E22: =VLOOKUP(C22,'Device Wise Uptime '!B:D,3,0) -> 99.870716 | F22: =VLOOKUP(C22,'Device Wise Uptime '!B:F,5,0) -> 97.495046
A23: 22 | B23: Mohali | C23: Q5AR-TEZ8-EZVW | D23: AP | E23: =VLOOKUP(C23,'Device Wise Uptime '!B:D,3,0) -> 99.991404 | F23: =VLOOKUP(C23,'Device Wise Uptime '!B:F,5,0) -> 99.658584
A24: 23 | B24: Mohali | C24: Q5JG-NJW9-ABBQ | D24: SW | E24: =VLOOKUP(C24,'Device Wise Uptime '!B:D,3,0) -> 99.996698 | F24: =VLOOKUP(C24,'Device Wise Uptime '!B:F,5,0) -> 98.648086
A25: 24 | B25: Mohali | C25: Q5JJ-3TZH-2HV5 | D25: SW | E25: =VLOOKUP(C25,'Device Wise Uptime '!B:D,3,0) -> 99.295108 | F25: =VLOOKUP(C25,'Device Wise Uptime '!B:F,5,0) -> 100
A26: 25 | B26: Hyderabad | C26: Q3KG-TLUW-VDX7 | D26: AP | E26: 100 | F26: 100
A27: 26 | B27: Hyderabad | C27: Q3KG-U9M3-9GEC | D27: AP | E27: 100 | F27: 100
A28: 27 | B28: Hyderabad | C28: Q3KG-UKZ7-TA5X | D28: AP | E28: 100 | F28: 100
A29: 28 | B29: Hyderabad | C29: Q5AA-23YU-R3GZ | D29: AP | E29: 100 | F29: 100
A30: 29 | B30: Hyderabad | C30: Q5AA-46QV-Z3ZC | D30: AP | E30: 100 | F30: 100
A31: 30 | B31: Hyderabad | C31: Q5AA-6EJ5-AG7V | D31: AP | E31: 100 | F31: 100
A32: 31 | B32: Hyderabad | C32: Q5AA-GAFW-R58M | D32: AP | E32: 100 | F32: 100
A33: 32 | B33: Hyderabad | C33: Q5AA-Q8AL-KHWV | D33: AP | E33: 100 | F33: 100
A34: 33 | B34: Hyderabad | C34: Q5AA-QLUG-NSPB | D34: AP | E34: 100 | F34: 100
A35: 34 | B35: Hyderabad | C35: Q5AA-R4B3-WH9P | D35: AP | E35: 100 | F35: 100
A36: 35 | B36: Hyderabad | C36: Q5AA-TRMY-596Z | D36: AP | E36: 100 | F36: 100
A37: 36 | B37: Hyderabad | C37: Q5AA-YR33-H6HL | D37: AP | E37: 100 | F37: 100
... A41: 40 | B41: Hyderabad | C41: Q5JJ-Q88T-6XC7 | D41: SW | E41: 100 | F41: 100
A42: 41 | B42: Nagpur | C42: Q3KG-FBVZ-2RBN | D42: AP | E42: =VLOOKUP(C42,'Device Wise Uptime '!B:D,3,0) -> 99.982539 | F42: =VLOOKUP(C42,'Device Wise Uptime '!B:F,5,0) -> 94.118711
A43: 42 | B43: Nagpur | C43: Q3KG-MBCN-DSBC | D43: AP | E43: =VLOOKUP(C43,'Device Wise Uptime '!B:D,3,0) -> 99.994151 | F43: =VLOOKUP(C43,'Device Wise Uptime '!B:F,5,0) -> 99.977068
...

Sheet BLR
C1: Values
A2: Location | B2: Serial No. | C2: Average of Average of Proactive -Uptime% | D2: Average of Average of JFL -Uptime %
A3: Bangalore | B3: Q2QW-EXXK-QDZ3 | C3: 99.995197 | D3: 75.047114
B4: Q2QW-BWS8-7ULR | C4: 99.987369 | D4: 89.268866
B5: Q3AC-DZAX-3FNP | C5: 99.994807 | D5: 90.534336
B6: Q3AC-Y2HS-V29M | C6: 99.995656 | D6: 90.534931
B7: Q2DW-FPMF-3AL6 | C7: 99.992377 | D7: 93.778565
B8: Q3AC-RQJS-FY3M | C8: 99.996092 | D8: 94.169784
B9: Q3AC-E8LA-PVD4 | C9: 99.99169 | D9: 95.093349
B10: Q3AC-MPKF-FE8T | C10: 99.992515 | D10: 96.01831
B11: Q2QW-BWVG-Y4ZU | C11: 99.989568 | D11: 96.658063
B12: Q3AC-86YA-CET5 | C12: 99.995756 | D12: 97.80608
B13: Q3AC-ZNCZ-HDNM | C13: 99.998171 | D13: 97.806713
B14: Q5AE-KNH9-5GV8 | C14: 99.99566 | D14: 98.416381
B15: Q2QW-CTFM-KEQZ | C15: 99.995806 | D15: 98.728245
... B184: Q5AE-Y9U3-MTM2 | C184: 100 | D184: 100
A185: Grand Total | C185: 99.954433 | D185: 99.461385

Sheet Grater Noida 
C1: Values
A2: Location | B2: Serial No. | C2: Average of Average of Proactive -Uptime% | D2: Average of Average of JFL -Uptime %
A3: Greater Noida | B3: Q3KG-A9R2-ATYY | C3: 99.978384 | D3: 87.02335
B4: Q5AA-LCK3-FDNW | C4: 99.95492 | D4: 90.036979
B5: JIN2117106B | C5: 99.831968 | D5: 92.439352
B6: FCW2110B27N | C6: 99.973148 | D6: 92.498727
B7: FCW2110B25A | C7: 100.53787 | D7: 94.207909
B8: FOC2039V1JW | C8: 99.814468 | D8: 94.299267
B9: Q3KG-GWW5-CHJC | C9: 99.984956 | D9: 94.775607
B10: Q3KG-6BJV-TZA3 | C10: 99.981168 | D10: 94.906366
B11: Q3KG-JH9T-FL7Z | C11: 100.11295 | D11: 95.673907
B12: Q5AA-FTAU-94AS | C12: 99.981119 | D12: 96.535594
B13: FJC290222SV | C13: 99.986088 | D13: 96.585208
B14: Q5AA-GHXM-TRTK | C14: 99.961089 | D14: 96.74655
B15: Q3KG-X73V-EYFZ | C15: 99.989545 | D15: 96.761497
... B115: FJC29021TWN | C115: 100 | D115: 100
A116: Grand Total | C116: 99.977613 | D116: 98.938845

Sheet Guwahati
C1: Values
A2: Location | B2: Serial No. | C2: Average of Average of Proactive -Uptime% | D2: Average of Average of JFL -Uptime %
A3: Guwahati | B3: Q5JG-AQNW-P9FB | C3: 99.987369 | D3: 98.978071
B4: Q5JG-ECTW-5MN7 | C4: 99.993474 | D4: 99.121968
B5: Q3KG-ZJZJ-WWH5 | C5: 99.991485 | D5: 99.36016
B6: Q5AA-RM28-C2R8 | C6: 99.993573 | D6: 99.554988
B7: Q5AR-T7UY-LJRT | C7: 100 | D7: 100
A8: Grand Total | C8: 99.99318 | D8: 99.403037

Sheet Hyd
C1: Values
A2: Location | B2: Serial No. | C2: Average of Average of Proactive -Uptime% | D2: Average of Average of JFL -Uptime %
A3: Hyderabad | B3: Q3KG-TLUW-VDX7 | C3: 100 | D3: 100
B4: Q3KG-U9M3-9GEC | C4: 100 | D4: 100
B5: Q3KG-UKZ7-TA5X | C5: 100 | D5: 100
B6: Q5AA-23YU-R3GZ | C6: 100 | D6: 100
B7: Q5AA-46QV-Z3ZC | C7: 100 | D7: 100
B8: Q5AA-6EJ5-AG7V | C8: 100 | D8: 100
B9: Q5AA-GAFW-R58M | C9: 100 | D9: 100
B10: Q5AA-Q8AL-KHWV | C10: 100 | D10: 100
B11: Q5AA-QLUG-NSPB | C11: 100 | D11: 100
B12: Q5AA-R4B3-WH9P | C12: 100 | D12: 100
B13: Q5AA-TRMY-596Z | C13: 100 | D13: 100
B14: Q5AA-YR33-H6HL | C14: 100 | D14: 100
B15: Q5AR-LXCJ-F26L | C15: 100 | D15: 100
... B18: Q5JJ-Q88T-6XC7 | C18: 100 | D18: 100
A19: Grand Total | C19: 100 | D19: 100

Sheet mohali
C1: Values
A2: Location | B2: Serial No. | C2: Average of Average of Proactive -Uptime% | D2: Average of Average of JFL -Uptime %
A3: Mohali | B3: Q3LP-2PSJ-6DLB | C3: 99.914029 | D3: 95.870848
B4: Q5AR-A7VQ-MZJM | C4: 99.870716 | D4: 97.495046
B5: Q5AA-E8FN-53RX | C5: 99.707859 | D5: 98.374745
B6: Q5JG-NJW9-ABBQ | C6: 99.996698 | D6: 98.648086
B7: Q5AA-MHPW-2YA8 | C7: 99.994414 | D7: 98.670513
B8: Q5AA-43RJ-JQUD | C8: 99.427816 | D8: 98.805324
B9: Q3LM-TGAF-Q97P | C9: 99.803547 | D9: 98.868315
B10: Q5AA-8PQC-7V98 | C10: 99.99233 | D10: 98.933086
B11: Q5AA-KHJW-U94C | C11: 99.712492 | D11: 99.137407
B12: Q3KG-9RDD-U5HG | C12: 99.991992 | D12: 99.264852
B13: Q5AR-56BZ-6TSR | C13: 99.706231 | D13: 99.327087
B14: Q3KG-Y9ZZ-W8HK | C14: 99.989302 | D14: 99.328985
B15: Q5AA-V3D8-DKEG | C15: 99.997056 | D15: 99.492928
... B21: Q5JJ-3TZH-2HV5 | C21: 99.295108 | D21: 100
A22: Grand Total | C22: 99.862108 | D22: 99.010904

Sheet Mumbai
C1: Values
A2: Location | B2: Serial No. | C2: Average of Average of Proactive -Uptime% | D2: Average of Average of JFL -Uptime %
A3: Mumbai | B3: FCW2302AHDZ | C3: 100 | D3: 100
B4: FCW2302D0Z7 | C4: 100 | D4: 100
B5: FCW2302D0ZJ | C5: 100 | D5: 100
B6: FCW2302DHGQ | C6: 100 | D6: 100
B7: FCW2302DHTU | C7: 100 | D7: 100
B8: FCW2302G0TL | C8: 100 | D8: 100
B9: FCW2302L13B | C9: 100 | D9: 100
B10: FOC2302U0WY | C10: 100 | D10: 100
A11: Grand Total | C11: 100 | D11: 100

Sheet Nagpur
C1: Values
A2: Location | B2: Serial No. | C2: Average of Average of Proactive -Uptime% | D2: Average of Average of JFL -Uptime %
A3: Nagpur | B3: Q3KG-FBVZ-2RBN | C3: 99.982539 | D3: 94.118711
B4: Q5JJ-68KZ-MXAS | C4: 99.989283 | D4: 96.040346
B5: Q5JG-TM9S-PLFP | C5: 99.983375 | D5: 96.908385
B6: Q3KG-P7GS-UMEQ | C6: 99.99635 | D6: 99.976289
B7: Q3KG-MBCN-DSBC | C7: 99.994151 | D7: 99.977068
B8: Q5AR-4FGW-G4PW | C8: 99.992346 | D8: 99.978488
B9: Q5JG-STQ9-EUPF | C9: 99.988854 | D9: 99.99054
B10: Q5JG-SL55-CZ9Z | C10: 99.986304 | D10: 99.990579
B11: Q5AA-XH9E-KZRJ | C11: 100 | D11: 100
B12: Q5AR-9UF6-M73Y | C12: 100 | D12: 100
A13: Grand Total | C13: 99.99132 | D13: 98.698041

Sheet Noida
C1: Values
A2: Location | B2: Serial No. | C2: Average of Average of Proactive -Uptime% | D2: Average of Average of JFL -Uptime %
A3: Noida | B3: FGL2708LJWX | C3: 99.977261 | D3: 95.772299
B4: FGL2717MEB1 | C4: 100 | D4: 100
B5: FJC2649217U | C5: 100 | D5: 100
B6: FDO2649M0JT | C6: 100 | D6: 100
B7: FJC283311U3 | C7: 100 | D7: 100
B8: FGL2708LJTX | C8: 100 | D8: 100
B9: FJC283311U5 | C9: 100 | D9: 100
B10: FGL2708LJU0 | C10: 100 | D10: 100
B11: FOC2635Y89M | C11: 100 | D11: 100
B12: FGL2708LJU6 | C12: 100 | D12: 100
B13: FOC2635Y89T | C13: 100 | D13: 100
B14: FGL2708LJUC | C14: 100 | D14: 100
B15: FOC2646YCRH | C15: 100 | D15: 100
... B83: WZP23460YYF | C83: 100 | D83: 100
A84: Grand Total | C84: 99.999719 | D84: 99.947806
